running jedimaster.py
=======================
Running: jedicatalog > jeditransform > jedidistort > jedipaste> jediconvolve > jedipaste> jedirescale> jedinoise> jeditransform> jedidistort > jedipaste> jediconvolve> jedipaste> jedirescale>  jedinoise
              1           2               3             4          5              6           7           8          9               10           11         12            13           14           15  
              Allocated   Transformed     distorting    Embedding  Band 1/6       Embedding   Binning     Noise-ing  Transformed    Distorting    Embedding  Band 1/6      Embedding    Binning col  Noise-ing row
              radius      image           galaxy        image                     image       col         row        image          galaxy        image                    image(small)
                                                            
1. open the terminal, cd to that path, and type:
python jedimaster.py physics_setting/config
#####################################################################################################################################################

2. if there are only jedimaster.py and physics_setting, error is: 
OSError: [Errno 2] No such file or directory
#####################################################################################################################################################

3. if there is executable jedicatalog, error is this:

FITSIO status = 115: NULL input pointer
failed to find or open the following file: (ffopen)
simdatabase/doneall2/scaled_finalnew_galaxy_10.fits
Error: jedicatalog did not terminate correctly. Return code: 1.
#####################################################################################################################################################

4.if we add folder simdatabase, then error is this:

Traceback (most recent call last):
  File "jedimaster.py", line 76, in <module>
    run_process("jeditransform", ['./jeditransform', config['catalog_file'], config['dislist_file']])
  File "jedimaster.py", line 64, in run_process
    process = subprocess.Popen(args)
  File "/System/Library/Frameworks/Python.framework/Versions/2.7/lib/python2.7/subprocess.py", line 711, in __init__
    errread, errwrite)
  File "/System/Library/Frameworks/Python.framework/Versions/2.7/lib/python2.7/subprocess.py", line 1308, in _execute_child
    raise child_exception
OSError: [Errno 2] No such file or directory

#####################################################################################################################################################
5. if we add executable jeditransform,
/*to compile, run:
 *gcc -O3 jeditransform.c -o jedi_imadjust -lm -lcfitsio
 */
we get some text files inside trial_0 folder
we get this error:

Traceback (most recent call last):
  File "jedimaster.py", line 79, in <module>
    run_process("jedidistort", ['./jedidistort', config['nx'], config['ny'], config['dislist_file'], config['lenses_file'], config['pix_scale'], config['lens_z']])
  File "jedimaster.py", line 64, in run_process
    process = subprocess.Popen(args)
  File "/System/Library/Frameworks/Python.framework/Versions/2.7/lib/python2.7/subprocess.py", line 711, in __init__
    errread, errwrite)
  File "/System/Library/Frameworks/Python.framework/Versions/2.7/lib/python2.7/subprocess.py", line 1308, in _execute_child
    raise child_exception
OSError: [Errno 2] No such file or directory
#####################################################################################################################################################

6. if we add executable jedidistort
/*to compile, run
 *gcc -O3 -g jedidistort.c -o jedidistort -lm -lcfitsio
 *to run,
 *./jedidistort 8192 8192 gallist.txt lenses.txt 0.05 0.3
 */
it runs for long time,
give error:
Error: jedidistort did not terminate correctly. Return code: 1.   # line 68 of jedimaster.py

